[2024-12-16T16:42:47.801+0000] {local_task_job_runner.py:123} INFO - ::group::Pre task execution logs
[2024-12-16T16:42:47.815+0000] {taskinstance.py:2613} INFO - Dependencies all met for dep_context=non-requeueable deps ti=<TaskInstance: PRCS_TEST_FRAMEWORK_DEPN_1.Run_bash_to_python_file manual__2024-12-16T16:19:00.128986+00:00 [queued]>
[2024-12-16T16:42:47.820+0000] {taskinstance.py:2613} INFO - Dependencies all met for dep_context=requeueable deps ti=<TaskInstance: PRCS_TEST_FRAMEWORK_DEPN_1.Run_bash_to_python_file manual__2024-12-16T16:19:00.128986+00:00 [queued]>
[2024-12-16T16:42:47.821+0000] {taskinstance.py:2866} INFO - Starting attempt 4 of 6
[2024-12-16T16:42:47.833+0000] {taskinstance.py:2889} INFO - Executing <Task(PythonOperator): Run_bash_to_python_file> on 2024-12-16 16:19:00.128986+00:00
[2024-12-16T16:42:47.840+0000] {logging_mixin.py:190} WARNING - /home/***/.local/lib/python3.12/site-packages/***/task/task_runner/standard_task_runner.py:70 DeprecationWarning: This process (pid=168) is multi-threaded, use of fork() may lead to deadlocks in the child.
[2024-12-16T16:42:47.841+0000] {standard_task_runner.py:104} INFO - Running: ['***', 'tasks', 'run', 'PRCS_TEST_FRAMEWORK_DEPN_1', 'Run_bash_to_python_file', 'manual__2024-12-16T16:19:00.128986+00:00', '--job-id', '1958', '--raw', '--subdir', 'DAGS_FOLDER/script/PRCS_TEST_FRAMEWORK_DEPN_1.py', '--cfg-path', '/tmp/tmpxyrg39ko']
[2024-12-16T16:42:47.844+0000] {standard_task_runner.py:72} INFO - Started process 199 to run task
[2024-12-16T16:42:47.844+0000] {standard_task_runner.py:105} INFO - Job 1958: Subtask Run_bash_to_python_file
[2024-12-16T16:42:47.890+0000] {task_command.py:467} INFO - Running <TaskInstance: PRCS_TEST_FRAMEWORK_DEPN_1.Run_bash_to_python_file manual__2024-12-16T16:19:00.128986+00:00 [running]> on host 3b6d26b512f1
[2024-12-16T16:42:48.099+0000] {taskinstance.py:3132} INFO - Exporting env vars: AIRFLOW_CTX_DAG_OWNER='test-framework' AIRFLOW_CTX_DAG_ID='PRCS_TEST_FRAMEWORK_DEPN_1' AIRFLOW_CTX_TASK_ID='Run_bash_to_python_file' AIRFLOW_CTX_EXECUTION_DATE='2024-12-16T16:19:00.128986+00:00' AIRFLOW_CTX_TRY_NUMBER='4' AIRFLOW_CTX_DAG_RUN_ID='manual__2024-12-16T16:19:00.128986+00:00'
[2024-12-16T16:42:48.101+0000] {taskinstance.py:731} INFO - ::endgroup::
[2024-12-16T16:42:48.111+0000] {local_task_job_runner.py:127} ERROR - Received SIGTERM. Terminating subprocesses
[2024-12-16T16:42:48.119+0000] {process_utils.py:132} INFO - Sending 15 to group 199. PIDs of all processes in the group: [199]
[2024-12-16T16:42:48.124+0000] {process_utils.py:87} INFO - Sending the signal 15 to group 199
[2024-12-16T16:42:48.131+0000] {taskinstance.py:3093} ERROR - Received SIGTERM. Terminating subprocesses.
[2024-12-16T16:42:48.150+0000] {taskinstance.py:3311} ERROR - Task failed with exception
Traceback (most recent call last):
  File "/home/airflow/.local/lib/python3.12/site-packages/airflow/models/taskinstance.py", line 767, in _execute_task
    result = _execute_callable(context=context, **execute_callable_kwargs)
             ^^^^^^^^^^^^^^^^^^^^^^^^^^^^^^^^^^^^^^^^^^^^^^^^^^^^^^^^^^^^^
  File "/home/airflow/.local/lib/python3.12/site-packages/airflow/models/taskinstance.py", line 733, in _execute_callable
    return ExecutionCallableRunner(
           ^^^^^^^^^^^^^^^^^^^^^^^^
  File "/home/airflow/.local/lib/python3.12/site-packages/airflow/utils/operator_helpers.py", line 252, in run
    return self.func(*args, **kwargs)
           ^^^^^^^^^^^^^^^^^^^^^^^^^^
  File "/home/airflow/.local/lib/python3.12/site-packages/airflow/models/baseoperator.py", line 402, in wrapper
    from airflow.decorators.base import DecoratedOperator
  File "/home/airflow/.local/lib/python3.12/site-packages/airflow/decorators/__init__.py", line 31, in <module>
    from airflow.decorators.setup_teardown import setup_task, teardown_task
  File "/home/airflow/.local/lib/python3.12/site-packages/airflow/decorators/setup_teardown.py", line 23, in <module>
    from airflow.decorators.task_group import _TaskGroupFactory
  File "/home/airflow/.local/lib/python3.12/site-packages/airflow/decorators/task_group.py", line 60, in <module>
    @attr.define()
     ^^^^^^^^^^^^^
  File "/home/airflow/.local/lib/python3.12/site-packages/attr/_next_gen.py", line 402, in wrap
    return do_it(cls, True)
           ^^^^^^^^^^^^^^^^
  File "/home/airflow/.local/lib/python3.12/site-packages/attr/_next_gen.py", line 348, in do_it
    return attrs(
           ^^^^^^
  File "/home/airflow/.local/lib/python3.12/site-packages/attr/_make.py", line 1396, in attrs
    return wrap(maybe_cls)
           ^^^^^^^^^^^^^^^
  File "/home/airflow/.local/lib/python3.12/site-packages/attr/_make.py", line 1375, in wrap
    builder.add_init()
  File "/home/airflow/.local/lib/python3.12/site-packages/attr/_make.py", line 962, in add_init
    _make_init(
  File "/home/airflow/.local/lib/python3.12/site-packages/attr/_make.py", line 1868, in _make_init
    init = _make_method(
           ^^^^^^^^^^^^^
  File "/home/airflow/.local/lib/python3.12/site-packages/attr/_make.py", line 242, in _make_method
    _compile_and_eval(script, globs, locs, filename)
  File "/home/airflow/.local/lib/python3.12/site-packages/attr/_make.py", line 214, in _compile_and_eval
    bytecode = compile(script, filename, "exec")
               ^^^^^^^^^^^^^^^^^^^^^^^^^^^^^^^^^
  File "/home/airflow/.local/lib/python3.12/site-packages/airflow/models/taskinstance.py", line 3095, in signal_handler
    raise AirflowTaskTerminated("Task received SIGTERM signal")
airflow.exceptions.AirflowTaskTerminated: Task received SIGTERM signal
[2024-12-16T16:42:48.160+0000] {taskinstance.py:1225} INFO - Marking task as UP_FOR_RETRY. dag_id=PRCS_TEST_FRAMEWORK_DEPN_1, task_id=Run_bash_to_python_file, run_id=manual__2024-12-16T16:19:00.128986+00:00, execution_date=20241216T161900, start_date=20241216T164247, end_date=20241216T164248
[2024-12-16T16:42:48.175+0000] {taskinstance.py:340} INFO - ::group::Post task execution logs
[2024-12-16T16:42:48.186+0000] {process_utils.py:80} INFO - Process psutil.Process(pid=199, status='terminated', exitcode=2, started='16:42:47') (199) terminated with exit code 2
[2024-12-16T16:42:48.186+0000] {local_task_job_runner.py:266} INFO - Task exited with return code 143
[2024-12-16T16:42:48.204+0000] {taskinstance.py:3895} INFO - 0 downstream tasks scheduled from follow-on schedule check
